<?xml version="1.0"?>
<mujoco>
    <worldbody>
        <!-- Drapeau -->
        <geom type="plane" name="ground" size="5 5 0.1" material="ground_mat" rgba="0.2 0.3 0.4 1"/>
        <body name="flag" pos="0 0 2">
            <!-- Cylindre pour le mât du drapeau -->
            <geom type="capsule" size="0.05 1" material="flag_mat" rgba="0.8 0.1 0.1 1"/>
            <joint type="hinge" axis="0 1 0" pos="0 0 0"/>
            
            <!-- Boîte en haut du cylindre comme le drapeau -->
            <geom type="box" size="0.5 0.05 0.5" pos="0.5 0 0.5" material="flag_mat" rgba="0.8 0.1 0.1 1"/>
        </body>
    </worldbody>
    <option timestep="0.01" gravity="0 0 0"/>
    <asset>
        <material name="ground_mat" rgba="0.1 0.5 0.1 1"/>
        <material name="flag_mat" rgba="0.8 0.1 0.1 1"/>
    </asset>
</mujoco>
